#VRML_SIM V8.0.5 utf8
WorldInfo {
  info [
    "Description: WeBots Model of the UH Robot House"
    "Author: Nathan Burke <n.burke@natbur.com>"
    "Date: 18 Oct 2014"
  ]
  title "robot house"
  basicTimeStep 16
}
Viewpoint {
  orientation 0 0.917556 0.397607 3.14159
  position 1.5 12.5 -11
}
Background {
  skyColor [
    0.4 0.7 1
  ]
}
DirectionalLight {
  ambientIntensity 1
  direction -0.33 -1 -0.5
  castShadows TRUE
}
RobotHouse {
  wallHeight 0.6
}
DEF Person Solid {
  translation 3 0.9 -1
  children [
    Shape {
      appearance Appearance {
        material Material {
          diffuseColor 1 0.72549 0
        }
      }
      geometry Cylinder {
        height 1.8
        radius 0.3
      }
    }
  ]
  name "researcher"
  model "person"
  description "Simulation Placeholder for a person"
  boundingObject Cylinder {
    height 1.8
    radius 0.3
  }
  physics Physics {
    density -1
    mass 40
    centerOfMass [
      0 0 0
    ]
    inertiaMatrix [
      148.864 22.9022 148.864
      0 0 0
    ]
    damping Damping {
    }
  }
  locked TRUE
  translationStep 0
  rotationStep 0
}
DEF Sunflower Pioneer3dx {
  rotation 0 1 0 -1.5707
  name "sunflower1_1"
  controller "rosController"
  extensionSlot [
    DEF Nav_Sensors Group {
      children [
        GPS {
        }
        Compass {
        }
      ]
    }
    DEF Sunflower_Parts Transform {
      translation 0 -0.0975 0
      children [
        DEF HEAD Transform {
          translation 0 0.755 0.04
          rotation 0 1 0 1.5727
          children [
            ax12 {
              name "neck_lower"
              endPoint fp04_02 {
                endPoint [
                  ax12 {
                    name "neck_upper"
                  }
                ]
              }
            }
          ]
        }
        DEF TRAY Transform {
          translation 0 0.645 -0.01
          children [
            SliderJoint {
              jointParameters JointParameters {
                axis 0 0 -1
                minStop -0.005
                maxStop 0.1
              }
              device [
                LinearMotor {
                  name "tray"
                  acceleration 3
                  maxVelocity 2
                  minPosition -0.005
                  maxPosition 0.1
                  maxForce 2
                }
              ]
              endPoint Solid {
                translation 0 0 0.00804878
                rotation -1 0 0 0
                children [
                  DEF FRONT Transform {
                    translation 0 0 -0.11
                    children [
                      Shape {
                        appearance Appearance {
                          material Material {
                            diffuseColor 0.96 0.86 0.57
                          }
                        }
                        geometry Box {
                          size 0.325 0.18 0.01
                        }
                      }
                    ]
                  }
                  DEF BOTTOM Transform {
                    translation 0 -0.085 0.005
                    children [
                      Shape {
                        appearance Appearance {
                          material Material {
                            diffuseColor 0.96 0.86 0.57
                          }
                        }
                        geometry Box {
                          size 0.325 0.01 0.22
                        }
                      }
                    ]
                  }
                  DEF LEFT Transform {
                    translation 0.1575 -0.04 0.005
                    children [
                      Shape {
                        appearance Appearance {
                          material Material {
                            diffuseColor 0.96 0.86 0.57
                          }
                        }
                        geometry Box {
                          size 0.01 0.08 0.22
                        }
                      }
                    ]
                  }
                  DEF RIGHT Transform {
                    translation -0.1575 -0.04 0.005
                    children [
                      Shape {
                        appearance Appearance {
                          material Material {
                            diffuseColor 0.96 0.86 0.57
                          }
                        }
                        geometry Box {
                          size 0.01 0.08 0.22
                        }
                      }
                    ]
                  }
                ]
                boundingObject Box {
                  size 0.325 0.18 0.23
                }
                physics Physics {
                  density 100
                }
              }
            }
          ]
        }
        DEF LED_PANEL Transform {
          translation 0 0.7525 0.04
          children [
            LED {
              children [
                Shape {
                  appearance Appearance {
                    material Material {
                      ambientIntensity 0
                      shininess 0.5
                      transparency 0.5
                    }
                  }
                  geometry Box {
                    size 0.325 0.005 0.295
                  }
                }
              ]
              name "light"
              color [
                0 0 0
                0 0 1
                0 1 0
                0 1 1
                1 0 0
                1 0 1
                1 1 0
                1 1 1
              ]
            }
          ]
        }
        DEF LASER Transform {
          translation 0 0.245 -0.15
          children [
            HokuyoUrg04lxug01 {
              translation 0 0.0525 0
              name "front_laser"
              noise 0.001
            }
          ]
        }
        DEF BODY Transform {
          translation 0 0.245 0.04
          children [
            DEF SHELL Transform {
              translation 0 0.2525 0
              children [
                Shape {
                  appearance Appearance {
                    material Material {
                      diffuseColor 0.98 0.98 0.9
                    }
                  }
                  geometry Box {
                    size 0.33 0.5 0.3
                  }
                }
              ]
            }
          ]
        }
      ]
    }
  ]
}
