#VRML_SIM V8.0.5 utf8
# Sunflower 1 Robot on a Pioneer3dx base

PROTO Sunflower1 [
  field SFVec3f translation 0 0.0975 0 
  field SFRotation rotation 0 1 0 0 
  field SFString name "Sunflower1_1"
  field SFString controller "void"
  field SFString controllerArgs ""
  field SFBool synchronization TRUE 
  field MFNode endPoint [
  ]
]
{
  DEF Sunflower Pioneer3dx {
    translation IS translation
    rotation IS rotation
    name IS name
    controller IS controller
    controllerArgs IS controllerArgs
    synchronization IS synchronization
    extensionSlot [
      DEF Nav_Sensors Group {
        children [
          GPS {
          }
          Compass {
          }
		  DEF EXTENSION_SLOT Group {
            children IS extensions
          }
        ]
      }
      DEF Sunflower_Parts Transform {
        translation 0 -0.0975 0
        children [
          DEF TRAY Transform {
            translation 0 0.645 -0.01
            children [
              SliderJoint {
                jointParameters JointParameters {
                  axis 0 0 -1
                  maxStop 0.1
                }
                device [
                  LinearMotor {
                    name "tray"
                    acceleration 3
                    maxVelocity 2
                    maxForce 2
                  }
                ]
                endPoint Solid {
                  children [
                    Shape {
                      appearance Appearance {
                        material Material {
                          diffuseColor 0.96 0.86 0.57
                        }
                      }
                      geometry Box {
                        size 0.325 0.18 0.23
                      }
                    }
                  ]
                  boundingObject Box {
                    size 0.325 0.18 0.23
                  }
                  physics Physics {
                    density 100
                  }
                }
              }
            ]
          }
          DEF LED_PANEL Transform {
            translation 0 0.7525 0.04
            children [
              LED {
                children [
                  Shape {
                    appearance Appearance {
                      material Material {
                        ambientIntensity 0
                        shininess 0.5
                        transparency 0.5
                      }
                    }
                    geometry Box {
                      size 0.325 0.005 0.295
                    }
                  }
                ]
                name "light"
                color [
                  0 0 0
                  0 0 1
                  0 1 0
                  0 1 1
                  1 0 0
                  1 0 1
                  1 1 0
                  1 1 1
                ]
              }
            ]
          }
          DEF LASER Transform {
            translation 0 0.245 -0.15
            children [
              HokuyoUrg04lxug01 {
                translation 0 0.0525 0
                name "front_laser"
                noise 0.001
              }
            ]
          }
          DEF BODY Transform {
            translation 0 0.245 0.04
            children [
              DEF SHELL Transform {
                translation 0 0.2525 0
                children [
                  Shape {
                    appearance Appearance {
                      material Material {
                        diffuseColor 0.98 0.98 0.9
                      }
                    }
                    geometry Box {
                      size 0.33 0.5 0.3
                    }
                  }
                ]
              }
            ]
          }
          DEF HEAD Transform {
            translation 0 1.045 0
            children [
              DEF CAMERA Transform {
                translation 0 -0.02 -0.11
                children [
                  Camera {
                    translation 0 0 0.02
                    children [
                      Transform {
                        rotation 1 0 0 -1.5707
                        children [
                          Shape {
                            appearance Appearance {
                              material Material {
                                diffuseColor 0.07 0.07 0.07
                              }
                            }
                            geometry Cylinder {
                              height 0.04
                              radius 0.015
                            }
                          }
                        ]
                      }
                    ]
                    name "head_camera"
                    width 320
                    height 320
                    pixelSize 0.5
                  }
                ]
              }
              DEF EYE_L Transform {
                translation -0.06 0 -0.12
                rotation 0.989439 0.14495 0 1.5707
                children [
                  Shape {
                    appearance Appearance {
                      material Material {
                        diffuseColor 0.98 0.98 0.9
                      }
                    }
                    geometry Cylinder {
                      height 0.015
                      radius 0.03
                    }
                  }
                ]
              }
              DEF SHELL Transform {
                children [
                  Shape {
                    appearance Appearance {
                      material Material {
                        diffuseColor 0.5 0.5 0.5
                      }
                    }
                    geometry Cylinder {
                      bottom FALSE
                      height 0.1
                      radius 0.11
                    }
                  }
                ]
              }
              DEF EYE_R Transform {
                translation 0.06 0 -0.12
                rotation 0.989439 -0.14495 0 1.5707
                children [
                  Shape {
                    appearance Appearance {
                      material Material {
                        diffuseColor 0.98 0.98 0.9
                      }
                    }
                    geometry Cylinder {
                      height 0.015
                      radius 0.03
                    }
                  }
                ]
              }
            ]
          }
        ]
      }
    ]
  }
}